Workbook

Sheet REPORTE
A1: Nro Guia | B1: Fecha ingreso a Planta | C1: Cliente | D1: Estado | E1: TIPO DE ESTADO | F1: GESTIÓN REALIZADA | G1: Remito | H1: Servicio | I1: Destinatario | J1: Domicilio | K1: Localidad | L1: Distribuidor Recorrido | M1: Recibio | N1: Documento | O1: CP | P1: FECHA ULTIMO ESTADO | Q1: Zona Destino
A2: =IF(base!A2="","",base!A2) -> 6200000 | B2: =IF(base!BN2="","",base!BN2) -> 46303.625 | C2: =IF(base!C2="","",base!C2) -> ZETABURGOS SRL | D2: =IF(base!E2="","",base!E2) -> 1RVT - 1° VISITA | E2: =IF(base!BF2="","",base!BF2) | F2: =IF(D2="","",IF(OR(ISNUMBER(SEARCH("VISITA",D2)),ISNUMBER(SEARCH("RUTA",D2)),ISNUMBER(SEARCH("ARRIB",D2)),ISNUMBER(SEARCH("MATRIZ",D2)),ISNUMBER(SEARCH("PENDIENTE",D2))),"VISITA COORDINADA CON EL CLIENTE","N/A")) -> VISITA COORDINADA CON EL CLIENTE | G2: =IF(base!G2="","",base!G2) -> 001234 | H2: =IF(base!I2="","",base!I2) -> FLEX | I2: =IF(base!S2="","",base!S2) -> Prueba 0 | J2: =IF(base!T2="","",base!T2) -> Calle 123 Piso 2 | K2: =IF(base!U2="","",base!U2) | L2: =IF(base!Y2="","",base!Y2) | M2: =IF(base!AH2="","",base!AH2) | N2: =IF(base!AI2="","",base!AI2) -> 34.072273 | O2: =IF(base!BA2="","",base!BA2) -> 1875 | P2: =IF(base!BK2="","",base!BK2) -> 46303.806 | Q2: =IF(base!BS2="","",base!BS2)
A3: =IF(base!A3="","",base!A3) -> 6200001 | B3: =IF(base!BN3="","",base!BN3) -> 46303.625 | C3: =IF(base!C3="","",base!C3) -> ZETABURGOS SRL | D3: =IF(base!E3="","",base!E3) -> ENTREGADO | E3: =IF(base!BF3="","",base!BF3) | F3: =IF(D3="","",IF(OR(ISNUMBER(SEARCH("VISITA",D3)),ISNUMBER(SEARCH("RUTA",D3)),ISNUMBER(SEARCH("ARRIB",D3)),ISNUMBER(SEARCH("MATRIZ",D3)),ISNUMBER(SEARCH("PENDIENTE",D3))),"VISITA COORDINADA CON EL CLIENTE","N/A")) -> N/A | G3: ="#ABC" -> #ABC | H3: =IF(base!I3="","",base!I3) -> SAMEDAY | I3: =IF(base!S3="","",base!S3) -> Prueba 1 | J3: =IF(base!T3="","",base!T3) -> Calle 123 Piso 2 | K3: =IF(base!U3="","",base!U3) | L3: =IF(base!Y3="","",base!Y3) | M3: =IF(base!AH3="","",base!AH3) | N3: =IF(base!AI3="","",base!AI3) -> 34.072273 | O3: =IF(base!BA3="","",base!BA3) -> 1875 | P3: =IF(base!BK3="","",base!BK3) -> 46303.806 | Q3: =IF(base!BS3="","",base!BS3)
A4: =IF(base!A4="","",base!A4) -> 6200002 | B4: =IF(base!BN4="","",base!BN4) -> 46303.625 | C4: =IF(base!C4="","",base!C4) -> ZETABURGOS SRL | D4: =IF(base!E4="","",base!E4) -> REPROGRAMACIÓN | E4: =IF(base!BF4="","",base!BF4) | F4: =IF(D4="","",IF(OR(ISNUMBER(SEARCH("VISITA",D4)),ISNUMBER(SEARCH("RUTA",D4)),ISNUMBER(SEARCH("ARRIB",D4)),ISNUMBER(SEARCH("MATRIZ",D4)),ISNUMBER(SEARCH("PENDIENTE",D4))),"VISITA COORDINADA CON EL CLIENTE","N/A")) -> N/A | G4: =IF(base!G4="","",base!G4) -> 470123456 | H4: =IF(base!I4="","",base!I4) -> FLEX | I4: =IF(base!S4="","",base!S4) -> Prueba 2 | J4: =IF(base!T4="","",base!T4) -> Calle 123 Piso 2 | K4: =IF(base!U4="","",base!U4) | L4: =IF(base!Y4="","",base!Y4) | M4: =IF(base!AH4="","",base!AH4) | N4: =IF(base!AI4="","",base!AI4) -> 34.072273 | O4: =IF(base!BA4="","",base!BA4) -> 1875 | P4: =IF(base!BK4="","",base!BK4) -> 46303.806 | Q4: =IF(base!BS4="","",base!BS4)
A5: =IF(base!A5="","",base!A5) -> 6200003 | B5: =IF(base!BN5="","",base!BN5) -> 46303.625 | C5: =IF(base!C5="","",base!C5) -> ZETABURGOS SRL | D5: =IF(base!E5="","",base!E5) -> 1RVT - 1° VISITA | E5: =IF(base!BF5="","",base!BF5) | F5: =IF(D5="","",IF(OR(ISNUMBER(SEARCH("VISITA",D5)),ISNUMBER(SEARCH("RUTA",D5)),ISNUMBER(SEARCH("ARRIB",D5)),ISNUMBER(SEARCH("MATRIZ",D5)),ISNUMBER(SEARCH("PENDIENTE",D5))),"VISITA COORDINADA CON EL CLIENTE","N/A")) -> VISITA COORDINADA CON EL CLIENTE | G5: =IF(base!G5="","",base!G5) -> ABC001 | H5: =IF(base!I5="","",base!I5) -> SAMEDAY | I5: =IF(base!S5="","",base!S5) -> Prueba 3 | J5: =IF(base!T5="","",base!T5) -> Calle 123 Piso 2 | K5: =IF(base!U5="","",base!U5) | L5: =IF(base!Y5="","",base!Y5) | M5: =IF(base!AH5="","",base!AH5) | N5: =IF(base!AI5="","",base!AI5) -> 34.072273 | O5: =IF(base!BA5="","",base!BA5) -> 1875 | P5: =IF(base!BK5="","",base!BK5) -> 46303.806 | Q5: =IF(base!BS5="","",base!BS5)
A6: =IF(base!A6="","",base!A6) -> 6200004 | B6: =IF(base!BN6="","",base!BN6) -> 46303.625 | C6: =IF(base!C6="","",base!C6) -> ZETABURGOS SRL | D6: =IF(base!E6="","",base!E6) -> ENTREGADO | E6: =IF(base!BF6="","",base!BF6) | F6: =IF(D6="","",IF(OR(ISNUMBER(SEARCH("VISITA",D6)),ISNUMBER(SEARCH("RUTA",D6)),ISNUMBER(SEARCH("ARRIB",D6)),ISNUMBER(SEARCH("MATRIZ",D6)),ISNUMBER(SEARCH("PENDIENTE",D6))),"VISITA COORDINADA CON EL CLIENTE","N/A")) -> N/A | G6: =IF(base!G6="","",base!G6) -> 2000018857041302 | H6: =IF(base!I6="","",base!I6) -> FLEX | I6: =IF(base!S6="","",base!S6) -> Prueba 4 | J6: =IF(base!T6="","",base!T6) -> Calle 123 Piso 2 | K6: =IF(base!U6="","",base!U6) | L6: =IF(base!Y6="","",base!Y6) | M6: =IF(base!AH6="","",base!AH6) | N6: =IF(base!AI6="","",base!AI6) -> 34.072273 | O6: =IF(base!BA6="","",base!BA6) -> 1875 | P6: =IF(base!BK6="","",base!BK6) -> 46303.806 | Q6: =IF(base!BS6="","",base!BS6)
A7: =IF(base!A7="","",base!A7) -> 6200005 | B7: =IF(base!BN7="","",base!BN7) -> 46303.625 | C7: =IF(base!C7="","",base!C7) -> ZETABURGOS SRL | D7: =IF(base!E7="","",base!E7) -> REPROGRAMACIÓN | E7: =IF(base!BF7="","",base!BF7) | F7: =IF(D7="","",IF(OR(ISNUMBER(SEARCH("VISITA",D7)),ISNUMBER(SEARCH("RUTA",D7)),ISNUMBER(SEARCH("ARRIB",D7)),ISNUMBER(SEARCH("MATRIZ",D7)),ISNUMBER(SEARCH("PENDIENTE",D7))),"VISITA COORDINADA CON EL CLIENTE","N/A")) -> N/A | G7: =IF(base!G7="","",base!G7) -> 001234 | H7: =IF(base!I7="","",base!I7) -> FLEX | I7: =IF(base!S7="","",base!S7) -> Prueba 5 | J7: =IF(base!T7="","",base!T7) -> Calle 123 Piso 2 | K7: =IF(base!U7="","",base!U7) | L7: =IF(base!Y7="","",base!Y7) | M7: =IF(base!AH7="","",base!AH7) | N7: =IF(base!AI7="","",base!AI7) -> 34.072273 | O7: =IF(base!BA7="","",base!BA7) -> 1875 | P7: =IF(base!BK7="","",base!BK7) -> 46303.806 | Q7: =IF(base!BS7="","",base!BS7)
A8: =IF(base!A8="","",base!A8) -> 6200006 | B8: =IF(base!BN8="","",base!BN8) -> 46303.625 | C8: =IF(base!C8="","",base!C8) -> ZETABURGOS SRL | D8: =IF(base!E8="","",base!E8) -> 1RVT - 1° VISITA | E8: =IF(base!BF8="","",base!BF8) | F8: =IF(D8="","",IF(OR(ISNUMBER(SEARCH("VISITA",D8)),ISNUMBER(SEARCH("RUTA",D8)),ISNUMBER(SEARCH("ARRIB",D8)),ISNUMBER(SEARCH("MATRIZ",D8)),ISNUMBER(SEARCH("PENDIENTE",D8))),"VISITA COORDINADA CON EL CLIENTE","N/A")) -> VISITA COORDINADA CON EL CLIENTE | G8: ="#ABC" -> #ABC | H8: =IF(base!I8="","",base!I8) -> SAMEDAY | I8: =IF(base!S8="","",base!S8) -> Prueba 6 | J8: =IF(base!T8="","",base!T8) -> Calle 123 Piso 2 | K8: =IF(base!U8="","",base!U8) | L8: =IF(base!Y8="","",base!Y8) | M8: =IF(base!AH8="","",base!AH8) | N8: =IF(base!AI8="","",base!AI8) -> 34.072273 | O8: =IF(base!BA8="","",base!BA8) -> 1875 | P8: =IF(base!BK8="","",base!BK8) -> 46303.806 | Q8: =IF(base!BS8="","",base!BS8)
A9: =IF(base!A9="","",base!A9) -> 6200007 | B9: =IF(base!BN9="","",base!BN9) -> 46303.625 | C9: =IF(base!C9="","",base!C9) -> ZETABURGOS SRL | D9: =IF(base!E9="","",base!E9) -> ENTREGADO | E9: =IF(base!BF9="","",base!BF9) | F9: =IF(D9="","",IF(OR(ISNUMBER(SEARCH("VISITA",D9)),ISNUMBER(SEARCH("RUTA",D9)),ISNUMBER(SEARCH("ARRIB",D9)),ISNUMBER(SEARCH("MATRIZ",D9)),ISNUMBER(SEARCH("PENDIENTE",D9))),"VISITA COORDINADA CON EL CLIENTE","N/A")) -> N/A | G9: =IF(base!G9="","",base!G9) -> 470123456 | H9: =IF(base!I9="","",base!I9) -> FLEX | I9: =IF(base!S9="","",base!S9) -> Prueba 7 | J9: =IF(base!T9="","",base!T9) -> Calle 123 Piso 2 | K9: =IF(base!U9="","",base!U9) | L9: =IF(base!Y9="","",base!Y9) | M9: =IF(base!AH9="","",base!AH9) | N9: =IF(base!AI9="","",base!AI9) -> 34.072273 | O9: =IF(base!BA9="","",base!BA9) -> 1875 | P9: =IF(base!BK9="","",base!BK9) -> 46303.806 | Q9: =IF(base!BS9="","",base!BS9)
A10: =IF(base!A10="","",base!A10) -> 6200008 | B10: =IF(base!BN10="","",base!BN10) -> 46303.625 | C10: =IF(base!C10="","",base!C10) -> ZETABURGOS SRL | D10: =IF(base!E10="","",base!E10) -> REPROGRAMACIÓN | E10: =IF(base!BF10="","",base!BF10) | F10: =IF(D10="","",IF(OR(ISNUMBER(SEARCH("VISITA",D10)),ISNUMBER(SEARCH("RUTA",D10)),ISNUMBER(SEARCH("ARRIB",D10)),ISNUMBER(SEARCH("MATRIZ",D10)),ISNUMBER(SEARCH("PENDIENTE",D10))),"VISITA COORDINADA CON EL CLIENTE","N/A")) -> N/A | G10: =IF(base!G10="","",base!G10) -> ABC001 | H10: =IF(base!I10="","",base!I10) -> SAMEDAY | I10: =IF(base!S10="","",base!S10) -> Prueba 8 | J10: =IF(base!T10="","",base!T10) -> Calle 123 Piso 2 | K10: =IF(base!U10="","",base!U10) | L10: =IF(base!Y10="","",base!Y10) | M10: =IF(base!AH10="","",base!AH10) | N10: =IF(base!AI10="","",base!AI10) -> 34.072273 | O10: =IF(base!BA10="","",base!BA10) -> 1875 | P10: =IF(base!BK10="","",base!BK10) -> 46303.806 | Q10: =IF(base!BS10="","",base!BS10)
A11: =IF(base!A11="","",base!A11) -> 6200009 | B11: =IF(base!BN11="","",base!BN11) -> 46303.625 | C11: =IF(base!C11="","",base!C11) -> ZETABURGOS SRL | D11: =IF(base!E11="","",base!E11) -> 1RVT - 1° VISITA | E11: =IF(base!BF11="","",base!BF11) | F11: =IF(D11="","",IF(OR(ISNUMBER(SEARCH("VISITA",D11)),ISNUMBER(SEARCH("RUTA",D11)),ISNUMBER(SEARCH("ARRIB",D11)),ISNUMBER(SEARCH("MATRIZ",D11)),ISNUMBER(SEARCH("PENDIENTE",D11))),"VISITA COORDINADA CON EL CLIENTE","N/A")) -> VISITA COORDINADA CON EL CLIENTE | G11: =IF(base!G11="","",base!G11) -> 2000018857041302 | H11: =IF(base!I11="","",base!I11) -> FLEX | I11: =IF(base!S11="","",base!S11) -> Prueba 9 | J11: =IF(base!T11="","",base!T11) -> Calle 123 Piso 2 | K11: =IF(base!U11="","",base!U11) | L11: =IF(base!Y11="","",base!Y11) | M11: =IF(base!AH11="","",base!AH11) | N11: =IF(base!AI11="","",base!AI11) -> 34.072273 | O11: =IF(base!BA11="","",base!BA11) -> 1875 | P11: =IF(base!BK11="","",base!BK11) -> 46303.806 | Q11: =IF(base!BS11="","",base!BS11)
A12: =IF(base!A12="","",base!A12) -> 6200010 | B12: =IF(base!BN12="","",base!BN12) -> 46303.625 | C12: =IF(base!C12="","",base!C12) -> ZETABURGOS SRL | D12: =IF(base!E12="","",base!E12) -> ENTREGADO | E12: =IF(base!BF12="","",base!BF12) | F12: =IF(D12="","",IF(OR(ISNUMBER(SEARCH("VISITA",D12)),ISNUMBER(SEARCH("RUTA",D12)),ISNUMBER(SEARCH("ARRIB",D12)),ISNUMBER(SEARCH("MATRIZ",D12)),ISNUMBER(SEARCH("PENDIENTE",D12))),"VISITA COORDINADA CON EL CLIENTE","N/A")) -> N/A | G12: =IF(base!G12="","",base!G12) -> 001234 | H12: =IF(base!I12="","",base!I12) -> FLEX | I12: =IF(base!S12="","",base!S12) -> Prueba 10 | J12: =IF(base!T12="","",base!T12) -> Calle 123 Piso 2 | K12: =IF(base!U12="","",base!U12) | L12: =IF(base!Y12="","",base!Y12) | M12: =IF(base!AH12="","",base!AH12) | N12: =IF(base!AI12="","",base!AI12) -> 34.072273 | O12: =IF(base!BA12="","",base!BA12) -> 1875 | P12: =IF(base!BK12="","",base!BK12) -> 46303.806 | Q12: =IF(base!BS12="","",base!BS12)
A13: =IF(base!A13="","",base!A13) -> 6200011 | B13: =IF(base!BN13="","",base!BN13) -> 46303.625 | C13: =IF(base!C13="","",base!C13) -> ZETABURGOS SRL | D13: =IF(base!E13="","",base!E13) -> REPROGRAMACIÓN | E13: =IF(base!BF13="","",base!BF13) | F13: =IF(D13="","",IF(OR(ISNUMBER(SEARCH("VISITA",D13)),ISNUMBER(SEARCH("RUTA",D13)),ISNUMBER(SEARCH("ARRIB",D13)),ISNUMBER(SEARCH("MATRIZ",D13)),ISNUMBER(SEARCH("PENDIENTE",D13))),"VISITA COORDINADA CON EL CLIENTE","N/A")) -> N/A | G13: ="#ABC" -> #ABC | H13: =IF(base!I13="","",base!I13) -> SAMEDAY | I13: =IF(base!S13="","",base!S13) -> Prueba 11 | J13: =IF(base!T13="","",base!T13) -> Calle 123 Piso 2 | K13: =IF(base!U13="","",base!U13) | L13: =IF(base!Y13="","",base!Y13) | M13: =IF(base!AH13="","",base!AH13) | N13: =IF(base!AI13="","",base!AI13) -> 34.072273 | O13: =IF(base!BA13="","",base!BA13) -> 1875 | P13: =IF(base!BK13="","",base!BK13) -> 46303.806 | Q13: =IF(base!BS13="","",base!BS13)
A14: =IF(base!A14="","",base!A14) -> 6200012 | B14: =IF(base!BN14="","",base!BN14) -> 46303.625 | C14: =IF(base!C14="","",base!C14) -> ZETABURGOS SRL | D14: =IF(base!E14="","",base!E14) -> 1RVT - 1° VISITA | E14: =IF(base!BF14="","",base!BF14) | F14: =IF(D14="","",IF(OR(ISNUMBER(SEARCH("VISITA",D14)),ISNUMBER(SEARCH("RUTA",D14)),ISNUMBER(SEARCH("ARRIB",D14)),ISNUMBER(SEARCH("MATRIZ",D14)),ISNUMBER(SEARCH("PENDIENTE",D14))),"VISITA COORDINADA CON EL CLIENTE","N/A")) -> VISITA COORDINADA CON EL CLIENTE | G14: =IF(base!G14="","",base!G14) -> 470123456 | H14: =IF(base!I14="","",base!I14) -> FLEX | I14: =IF(base!S14="","",base!S14) -> Prueba 12 | J14: =IF(base!T14="","",base!T14) -> Calle 123 Piso 2 | K14: =IF(base!U14="","",base!U14) | L14: =IF(base!Y14="","",base!Y14) | M14: =IF(base!AH14="","",base!AH14) | N14: =IF(base!AI14="","",base!AI14) -> 34.072273 | O14: =IF(base!BA14="","",base!BA14) -> 1875 | P14: =IF(base!BK14="","",base!BK14) -> 46303.806 | Q14: =IF(base!BS14="","",base!BS14)
A15: =IF(base!A15="","",base!A15) -> 6200013 | B15: =IF(base!BN15="","",base!BN15) -> 46303.625 | C15: =IF(base!C15="","",base!C15) -> ZETABURGOS SRL | D15: =IF(base!E15="","",base!E15) -> ENTREGADO | E15: =IF(base!BF15="","",base!BF15) | F15: =IF(D15="","",IF(OR(ISNUMBER(SEARCH("VISITA",D15)),ISNUMBER(SEARCH("RUTA",D15)),ISNUMBER(SEARCH("ARRIB",D15)),ISNUMBER(SEARCH("MATRIZ",D15)),ISNUMBER(SEARCH("PENDIENTE",D15))),"VISITA COORDINADA CON EL CLIENTE","N/A")) -> N/A | G15: =IF(base!G15="","",base!G15) -> ABC001 | H15: =IF(base!I15="","",base!I15) -> SAMEDAY | I15: =IF(base!S15="","",base!S15) -> Prueba 13 | J15: =IF(base!T15="","",base!T15) -> Calle 123 Piso 2 | K15: =IF(base!U15="","",base!U15) | L15: =IF(base!Y15="","",base!Y15) | M15: =IF(base!AH15="","",base!AH15) | N15: =IF(base!AI15="","",base!AI15) -> 34.072273 | O15: =IF(base!BA15="","",base!BA15) -> 1875 | P15: =IF(base!BK15="","",base!BK15) -> 46303.806 | Q15: =IF(base!BS15="","",base!BS15)
A16: =IF(base!A16="","",base!A16) -> 6200014 | B16: =IF(base!BN16="","",base!BN16) -> 46303.625 | C16: =IF(base!C16="","",base!C16) -> ZETABURGOS SRL | D16: =IF(base!E16="","",base!E16) -> REPROGRAMACIÓN | E16: =IF(base!BF16="","",base!BF16) | F16: =IF(D16="","",IF(OR(ISNUMBER(SEARCH("VISITA",D16)),ISNUMBER(SEARCH("RUTA",D16)),ISNUMBER(SEARCH("ARRIB",D16)),ISNUMBER(SEARCH("MATRIZ",D16)),ISNUMBER(SEARCH("PENDIENTE",D16))),"VISITA COORDINADA CON EL CLIENTE","N/A")) -> N/A | G16: =IF(base!G16="","",base!G16) -> 2000018857041302 | H16: =IF(base!I16="","",base!I16) -> FLEX | I16: =IF(base!S16="","",base!S16) -> Prueba 14 | J16: =IF(base!T16="","",base!T16) -> Calle 123 Piso 2 | K16: =IF(base!U16="","",base!U16) | L16: =IF(base!Y16="","",base!Y16) | M16: =IF(base!AH16="","",base!AH16) | N16: =IF(base!AI16="","",base!AI16) -> 34.072273 | O16: =IF(base!BA16="","",base!BA16) -> 1875 | P16: =IF(base!BK16="","",base!BK16) -> 46303.806 | Q16: =IF(base!BS16="","",base!BS16)
A17: =IF(base!A17="","",base!A17) -> 6200015 | B17: =IF(base!BN17="","",base!BN17) -> 46303.625 | C17: =IF(base!C17="","",base!C17) -> ZETABURGOS SRL | D17: =IF(base!E17="","",base!E17) -> 1RVT - 1° VISITA | E17: =IF(base!BF17="","",base!BF17) | F17: =IF(D17="","",IF(OR(ISNUMBER(SEARCH("VISITA",D17)),ISNUMBER(SEARCH("RUTA",D17)),ISNUMBER(SEARCH("ARRIB",D17)),ISNUMBER(SEARCH("MATRIZ",D17)),ISNUMBER(SEARCH("PENDIENTE",D17))),"VISITA COORDINADA CON EL CLIENTE","N/A")) -> VISITA COORDINADA CON EL CLIENTE | G17: =IF(base!G17="","",base!G17) -> 001234 | H17: =IF(base!I17="","",base!I17) -> FLEX | I17: =IF(base!S17="","",base!S17) -> Prueba 15 | J17: =IF(base!T17="","",base!T17) -> Calle 123 Piso 2 | K17: =IF(base!U17="","",base!U17) | L17: =IF(base!Y17="","",base!Y17) | M17: =IF(base!AH17="","",base!AH17) | N17: =IF(base!AI17="","",base!AI17) -> 34.072273 | O17: =IF(base!BA17="","",base!BA17) -> 1875 | P17: =IF(base!BK17="","",base!BK17) -> 46303.806 | Q17: =IF(base!BS17="","",base!BS17)
A18: =IF(base!A18="","",base!A18) -> 6200016 | B18: =IF(base!BN18="","",base!BN18) -> 46303.625 | C18: =IF(base!C18="","",base!C18) -> ZETABURGOS SRL | D18: =IF(base!E18="","",base!E18) -> ENTREGADO | E18: =IF(base!BF18="","",base!BF18) | F18: =IF(D18="","",IF(OR(ISNUMBER(SEARCH("VISITA",D18)),ISNUMBER(SEARCH("RUTA",D18)),ISNUMBER(SEARCH("ARRIB",D18)),ISNUMBER(SEARCH("MATRIZ",D18)),ISNUMBER(SEARCH("PENDIENTE",D18))),"VISITA COORDINADA CON EL CLIENTE","N/A")) -> N/A | G18: ="#ABC" -> #ABC | H18: =IF(base!I18="","",base!I18) -> SAMEDAY | I18: =IF(base!S18="","",base!S18) -> Prueba 16 | J18: =IF(base!T18="","",base!T18) -> Calle 123 Piso 2 | K18: =IF(base!U18="","",base!U18) | L18: =IF(base!Y18="","",base!Y18) | M18: =IF(base!AH18="","",base!AH18) | N18: =IF(base!AI18="","",base!AI18) -> 34.072273 | O18: =IF(base!BA18="","",base!BA18) -> 1875 | P18: =IF(base!BK18="","",base!BK18) -> 46303.806 | Q18: =IF(base!BS18="","",base!BS18)
A19: =IF(base!A19="","",base!A19) -> 6200017 | B19: =IF(base!BN19="","",base!BN19) -> 46303.625 | C19: =IF(base!C19="","",base!C19) -> ZETABURGOS SRL | D19: =IF(base!E19="","",base!E19) -> REPROGRAMACIÓN | E19: =IF(base!BF19="","",base!BF19) | F19: =IF(D19="","",IF(OR(ISNUMBER(SEARCH("VISITA",D19)),ISNUMBER(SEARCH("RUTA",D19)),ISNUMBER(SEARCH("ARRIB",D19)),ISNUMBER(SEARCH("MATRIZ",D19)),ISNUMBER(SEARCH("PENDIENTE",D19))),"VISITA COORDINADA CON EL CLIENTE","N/A")) -> N/A | G19: =IF(base!G19="","",base!G19) -> 470123456 | H19: =IF(base!I19="","",base!I19) -> FLEX | I19: =IF(base!S19="","",base!S19) -> Prueba 17 | J19: =IF(base!T19="","",base!T19) -> Calle 123 Piso 2 | K19: =IF(base!U19="","",base!U19) | L19: =IF(base!Y19="","",base!Y19) | M19: =IF(base!AH19="","",base!AH19) | N19: =IF(base!AI19="","",base!AI19) -> 34.072273 | O19: =IF(base!BA19="","",base!BA19) -> 1875 | P19: =IF(base!BK19="","",base!BK19) -> 46303.806 | Q19: =IF(base!BS19="","",base!BS19)
A20: =IF(base!A20="","",base!A20) -> 6200018 | B20: =IF(base!BN20="","",base!BN20) -> 46303.625 | C20: =IF(base!C20="","",base!C20) -> ZETABURGOS SRL | D20: =IF(base!E20="","",base!E20) -> 1RVT - 1° VISITA | E20: =IF(base!BF20="","",base!BF20) | F20: =IF(D20="","",IF(OR(ISNUMBER(SEARCH("VISITA",D20)),ISNUMBER(SEARCH("RUTA",D20)),ISNUMBER(SEARCH("ARRIB",D20)),ISNUMBER(SEARCH("MATRIZ",D20)),ISNUMBER(SEARCH("PENDIENTE",D20))),"VISITA COORDINADA CON EL CLIENTE","N/A")) -> VISITA COORDINADA CON EL CLIENTE | G20: =IF(base!G20="","",base!G20) -> ABC001 | H20: =IF(base!I20="","",base!I20) -> SAMEDAY | I20: =IF(base!S20="","",base!S20) -> Prueba 18 | J20: =IF(base!T20="","",base!T20) -> Calle 123 Piso 2 | K20: =IF(base!U20="","",base!U20) | L20: =IF(base!Y20="","",base!Y20) | M20: =IF(base!AH20="","",base!AH20) | N20: =IF(base!AI20="","",base!AI20) -> 34.072273 | O20: =IF(base!BA20="","",base!BA20) -> 1875 | P20: =IF(base!BK20="","",base!BK20) -> 46303.806 | Q20: =IF(base!BS20="","",base!BS20)
A21: =IF(base!A21="","",base!A21) -> 6200019 | B21: =IF(base!BN21="","",base!BN21) -> 46303.625 | C21: =IF(base!C21="","",base!C21) -> ZETABURGOS SRL | D21: =IF(base!E21="","",base!E21) -> ENTREGADO | E21: =IF(base!BF21="","",base!BF21) | F21: =IF(D21="","",IF(OR(ISNUMBER(SEARCH("VISITA",D21)),ISNUMBER(SEARCH("RUTA",D21)),ISNUMBER(SEARCH("ARRIB",D21)),ISNUMBER(SEARCH("MATRIZ",D21)),ISNUMBER(SEARCH("PENDIENTE",D21))),"VISITA COORDINADA CON EL CLIENTE","N/A")) -> N/A | G21: =IF(base!G21="","",base!G21) -> 2000018857041302 | H21: =IF(base!I21="","",base!I21) -> FLEX | I21: =IF(base!S21="","",base!S21) -> Prueba 19 | J21: =IF(base!T21="","",base!T21) -> Calle 123 Piso 2 | K21: =IF(base!U21="","",base!U21) | L21: =IF(base!Y21="","",base!Y21) | M21: =IF(base!AH21="","",base!AH21) | N21: =IF(base!AI21="","",base!AI21) -> 34.072273 | O21: =IF(base!BA21="","",base!BA21) -> 1875 | P21: =IF(base!BK21="","",base!BK21) -> 46303.806 | Q21: =IF(base!BS21="","",base!BS21)
A22: =IF(base!A22="","",base!A22) -> 6200020 | B22: =IF(base!BN22="","",base!BN22) -> 46303.625 | C22: =IF(base!C22="","",base!C22) -> ZETABURGOS SRL | D22: =IF(base!E22="","",base!E22) -> REPROGRAMACIÓN | E22: =IF(base!BF22="","",base!BF22) | F22: =IF(D22="","",IF(OR(ISNUMBER(SEARCH("VISITA",D22)),ISNUMBER(SEARCH("RUTA",D22)),ISNUMBER(SEARCH("ARRIB",D22)),ISNUMBER(SEARCH("MATRIZ",D22)),ISNUMBER(SEARCH("PENDIENTE",D22))),"VISITA COORDINADA CON EL CLIENTE","N/A")) -> N/A | G22: =IF(base!G22="","",base!G22) -> 001234 | H22: =IF(base!I22="","",base!I22) -> FLEX | I22: =IF(base!S22="","",base!S22) -> Prueba 20 | J22: =IF(base!T22="","",base!T22) -> Calle 123 Piso 2 | K22: =IF(base!U22="","",base!U22) | L22: =IF(base!Y22="","",base!Y22) | M22: =IF(base!AH22="","",base!AH22) | N22: =IF(base!AI22="","",base!AI22) -> 34.072273 | O22: =IF(base!BA22="","",base!BA22) -> 1875 | P22: =IF(base!BK22="","",base!BK22) -> 46303.806 | Q22: =IF(base!BS22="","",base!BS22)
A23: =IF(base!A23="","",base!A23) -> 6200021 | B23: =IF(base!BN23="","",base!BN23) -> 46303.625 | C23: =IF(base!C23="","",base!C23) -> ZETABURGOS SRL | D23: =IF(base!E23="","",base!E23) -> 1RVT - 1° VISITA | E23: =IF(base!BF23="","",base!BF23) | F23: =IF(D23="","",IF(OR(ISNUMBER(SEARCH("VISITA",D23)),ISNUMBER(SEARCH("RUTA",D23)),ISNUMBER(SEARCH("ARRIB",D23)),ISNUMBER(SEARCH("MATRIZ",D23)),ISNUMBER(SEARCH("PENDIENTE",D23))),"VISITA COORDINADA CON EL CLIENTE","N/A")) -> VISITA COORDINADA CON EL CLIENTE | G23: ="#ABC" -> #ABC | H23: =IF(base!I23="","",base!I23) -> SAMEDAY | I23: =IF(base!S23="","",base!S23) -> Prueba 21 | J23: =IF(base!T23="","",base!T23) -> Calle 123 Piso 2 | K23: =IF(base!U23="","",base!U23) | L23: =IF(base!Y23="","",base!Y23) | M23: =IF(base!AH23="","",base!AH23) | N23: =IF(base!AI23="","",base!AI23) -> 34.072273 | O23: =IF(base!BA23="","",base!BA23) -> 1875 | P23: =IF(base!BK23="","",base!BK23) -> 46303.806 | Q23: =IF(base!BS23="","",base!BS23)
A24: =IF(base!A24="","",base!A24) -> 6200022 | B24: =IF(base!BN24="","",base!BN24) -> 46303.625 | C24: =IF(base!C24="","",base!C24) -> ZETABURGOS SRL | D24: =IF(base!E24="","",base!E24) -> ENTREGADO | E24: =IF(base!BF24="","",base!BF24) | F24: =IF(D24="","",IF(OR(ISNUMBER(SEARCH("VISITA",D24)),ISNUMBER(SEARCH("RUTA",D24)),ISNUMBER(SEARCH("ARRIB",D24)),ISNUMBER(SEARCH("MATRIZ",D24)),ISNUMBER(SEARCH("PENDIENTE",D24))),"VISITA COORDINADA CON EL CLIENTE","N/A")) -> N/A | G24: =IF(base!G24="","",base!G24) -> 470123456 | H24: =IF(base!I24="","",base!I24) -> FLEX | I24: =IF(base!S24="","",base!S24) -> Prueba 22 | J24: =IF(base!T24="","",base!T24) -> Calle 123 Piso 2 | K24: =IF(base!U24="","",base!U24) | L24: =IF(base!Y24="","",base!Y24) | M24: =IF(base!AH24="","",base!AH24) | N24: =IF(base!AI24="","",base!AI24) -> 34.072273 | O24: =IF(base!BA24="","",base!BA24) -> 1875 | P24: =IF(base!BK24="","",base!BK24) -> 46303.806 | Q24: =IF(base!BS24="","",base!BS24)
A25: =IF(base!A25="","",base!A25) -> 6200023 | B25: =IF(base!BN25="","",base!BN25) -> 46303.625 | C25: =IF(base!C25="","",base!C25) -> ZETABURGOS SRL | D25: =IF(base!E25="","",base!E25) -> REPROGRAMACIÓN | E25: =IF(base!BF25="","",base!BF25) | F25: =IF(D25="","",IF(OR(ISNUMBER(SEARCH("VISITA",D25)),ISNUMBER(SEARCH("RUTA",D25)),ISNUMBER(SEARCH("ARRIB",D25)),ISNUMBER(SEARCH("MATRIZ",D25)),ISNUMBER(SEARCH("PENDIENTE",D25))),"VISITA COORDINADA CON EL CLIENTE","N/A")) -> N/A | G25: =IF(base!G25="","",base!G25) -> ABC001 | H25: =IF(base!I25="","",base!I25) -> SAMEDAY | I25: =IF(base!S25="","",base!S25) -> Prueba 23 | J25: =IF(base!T25="","",base!T25) -> Calle 123 Piso 2 | K25: =IF(base!U25="","",base!U25) | L25: =IF(base!Y25="","",base!Y25) | M25: =IF(base!AH25="","",base!AH25) | N25: =IF(base!AI25="","",base!AI25) -> 34.072273 | O25: =IF(base!BA25="","",base!BA25) -> 1875 | P25: =IF(base!BK25="","",base!BK25) -> 46303.806 | Q25: =IF(base!BS25="","",base!BS25)
A26: =IF(base!A26="","",base!A26) -> 6200024 | B26: =IF(base!BN26="","",base!BN26) -> 46303.625 | C26: =IF(base!C26="","",base!C26) -> ZETABURGOS SRL | D26: =IF(base!E26="","",base!E26) -> 1RVT - 1° VISITA | E26: =IF(base!BF26="","",base!BF26) | F26: =IF(D26="","",IF(OR(ISNUMBER(SEARCH("VISITA",D26)),ISNUMBER(SEARCH("RUTA",D26)),ISNUMBER(SEARCH("ARRIB",D26)),ISNUMBER(SEARCH("MATRIZ",D26)),ISNUMBER(SEARCH("PENDIENTE",D26))),"VISITA COORDINADA CON EL CLIENTE","N/A")) -> VISITA COORDINADA CON EL CLIENTE | G26: =IF(base!G26="","",base!G26) -> 2000018857041302 | H26: =IF(base!I26="","",base!I26) -> FLEX | I26: =IF(base!S26="","",base!S26) -> Prueba 24 | J26: =IF(base!T26="","",base!T26) -> Calle 123 Piso 2 | K26: =IF(base!U26="","",base!U26) | L26: =IF(base!Y26="","",base!Y26) | M26: =IF(base!AH26="","",base!AH26) | N26: =IF(base!AI26="","",base!AI26) -> 34.072273 | O26: =IF(base!BA26="","",base!BA26) -> 1875 | P26: =IF(base!BK26="","",base!BK26) -> 46303.806 | Q26: =IF(base!BS26="","",base!BS26)
A27: =IF(base!A27="","",base!A27) -> 6200025 | B27: =IF(base!BN27="","",base!BN27) -> 46303.625 | C27: =IF(base!C27="","",base!C27) -> ZETABURGOS SRL | D27: =IF(base!E27="","",base!E27) -> ENTREGADO | E27: =IF(base!BF27="","",base!BF27) | F27: =IF(D27="","",IF(OR(ISNUMBER(SEARCH("VISITA",D27)),ISNUMBER(SEARCH("RUTA",D27)),ISNUMBER(SEARCH("ARRIB",D27)),ISNUMBER(SEARCH("MATRIZ",D27)),ISNUMBER(SEARCH("PENDIENTE",D27))),"VISITA COORDINADA CON EL CLIENTE","N/A")) -> N/A | G27: =IF(base!G27="","",base!G27) -> 001234 | H27: =IF(base!I27="","",base!I27) -> FLEX | I27: =IF(base!S27="","",base!S27) -> Prueba 25 | J27: =IF(base!T27="","",base!T27) -> Calle 123 Piso 2 | K27: =IF(base!U27="","",base!U27) | L27: =IF(base!Y27="","",base!Y27) | M27: =IF(base!AH27="","",base!AH27) | N27: =IF(base!AI27="","",base!AI27) -> 34.072273 | O27: =IF(base!BA27="","",base!BA27) -> 1875 | P27: =IF(base!BK27="","",base!BK27) -> 46303.806 | Q27: =IF(base!BS27="","",base!BS27)
A28: =IF(base!A28="","",base!A28) -> 6200026 | B28: =IF(base!BN28="","",base!BN28) -> 46303.625 | C28: =IF(base!C28="","",base!C28) -> ZETABURGOS SRL | D28: =IF(base!E28="","",base!E28) -> REPROGRAMACIÓN | E28: =IF(base!BF28="","",base!BF28) | F28: =IF(D28="","",IF(OR(ISNUMBER(SEARCH("VISITA",D28)),ISNUMBER(SEARCH("RUTA",D28)),ISNUMBER(SEARCH("ARRIB",D28)),ISNUMBER(SEARCH("MATRIZ",D28)),ISNUMBER(SEARCH("PENDIENTE",D28))),"VISITA COORDINADA CON EL CLIENTE","N/A")) -> N/A | G28: ="#ABC" -> #ABC | H28: =IF(base!I28="","",base!I28) -> SAMEDAY | I28: =IF(base!S28="","",base!S28) -> Prueba 26 | J28: =IF(base!T28="","",base!T28) -> Calle 123 Piso 2 | K28: =IF(base!U28="","",base!U28) | L28: =IF(base!Y28="","",base!Y28) | M28: =IF(base!AH28="","",base!AH28) | N28: =IF(base!AI28="","",base!AI28) -> 34.072273 | O28: =IF(base!BA28="","",base!BA28) -> 1875 | P28: =IF(base!BK28="","",base!BK28) -> 46303.806 | Q28: =IF(base!BS28="","",base!BS28)
A29: =IF(base!A29="","",base!A29) -> 6200027 | B29: =IF(base!BN29="","",base!BN29) -> 46303.625 | C29: =IF(base!C29="","",base!C29) -> ZETABURGOS SRL | D29: =IF(base!E29="","",base!E29) -> 1RVT - 1° VISITA | E29: =IF(base!BF29="","",base!BF29) | F29: =IF(D29="","",IF(OR(ISNUMBER(SEARCH("VISITA",D29)),ISNUMBER(SEARCH("RUTA",D29)),ISNUMBER(SEARCH("ARRIB",D29)),ISNUMBER(SEARCH("MATRIZ",D29)),ISNUMBER(SEARCH("PENDIENTE",D29))),"VISITA COORDINADA CON EL CLIENTE","N/A")) -> VISITA COORDINADA CON EL CLIENTE | G29: =IF(base!G29="","",base!G29) -> 470123456 | H29: =IF(base!I29="","",base!I29) -> FLEX | I29: =IF(base!S29="","",base!S29) -> Prueba 27 | J29: =IF(base!T29="","",base!T29) -> Calle 123 Piso 2 | K29: =IF(base!U29="","",base!U29) | L29: =IF(base!Y29="","",base!Y29) | M29: =IF(base!AH29="","",base!AH29) | N29: =IF(base!AI29="","",base!AI29) -> 34.072273 | O29: =IF(base!BA29="","",base!BA29) -> 1875 | P29: =IF(base!BK29="","",base!BK29) -> 46303.806 | Q29: =IF(base!BS29="","",base!BS29)
A30: =IF(base!A30="","",base!A30) -> 6200028 | B30: =IF(base!BN30="","",base!BN30) -> 46303.625 | C30: =IF(base!C30="","",base!C30) -> ZETABURGOS SRL | D30: =IF(base!E30="","",base!E30) -> ENTREGADO | E30: =IF(base!BF30="","",base!BF30) | F30: =IF(D30="","",IF(OR(ISNUMBER(SEARCH("VISITA",D30)),ISNUMBER(SEARCH("RUTA",D30)),ISNUMBER(SEARCH("ARRIB",D30)),ISNUMBER(SEARCH("MATRIZ",D30)),ISNUMBER(SEARCH("PENDIENTE",D30))),"VISITA COORDINADA CON EL CLIENTE","N/A")) -> N/A | G30: =IF(base!G30="","",base!G30) -> ABC001 | H30: =IF(base!I30="","",base!I30) -> SAMEDAY | I30: =IF(base!S30="","",base!S30) -> Prueba 28 | J30: =IF(base!T30="","",base!T30) -> Calle 123 Piso 2 | K30: =IF(base!U30="","",base!U30) | L30: =IF(base!Y30="","",base!Y30) | M30: =IF(base!AH30="","",base!AH30) | N30: =IF(base!AI30="","",base!AI30) -> 34.072273 | O30: =IF(base!BA30="","",base!BA30) -> 1875 | P30: =IF(base!BK30="","",base!BK30) -> 46303.806 | Q30: =IF(base!BS30="","",base!BS30)
A31: =IF(base!A31="","",base!A31) -> 6200029 | B31: =IF(base!BN31="","",base!BN31) -> 46303.625 | C31: =IF(base!C31="","",base!C31) -> ZETABURGOS SRL | D31: =IF(base!E31="","",base!E31) -> REPROGRAMACIÓN | E31: =IF(base!BF31="","",base!BF31) | F31: =IF(D31="","",IF(OR(ISNUMBER(SEARCH("VISITA",D31)),ISNUMBER(SEARCH("RUTA",D31)),ISNUMBER(SEARCH("ARRIB",D31)),ISNUMBER(SEARCH("MATRIZ",D31)),ISNUMBER(SEARCH("PENDIENTE",D31))),"VISITA COORDINADA CON EL CLIENTE","N/A")) -> N/A | G31: =IF(base!G31="","",base!G31) -> 2000018857041302 | H31: =IF(base!I31="","",base!I31) -> FLEX | I31: =IF(base!S31="","",base!S31) -> Prueba 29 | J31: =IF(base!T31="","",base!T31) -> Calle 123 Piso 2 | K31: =IF(base!U31="","",base!U31) | L31: =IF(base!Y31="","",base!Y31) | M31: =IF(base!AH31="","",base!AH31) | N31: =IF(base!AI31="","",base!AI31) -> 34.072273 | O31: =IF(base!BA31="","",base!BA31) -> 1875 | P31: =IF(base!BK31="","",base!BK31) -> 46303.806 | Q31: =IF(base!BS31="","",base!BS31)
A32: =IF(base!A32="","",base!A32) -> 6200030 | B32: =IF(base!BN32="","",base!BN32) -> 46303.625 | C32: =IF(base!C32="","",base!C32) -> ZETABURGOS SRL | D32: =IF(base!E32="","",base!E32) -> 1RVT - 1° VISITA | E32: =IF(base!BF32="","",base!BF32) | F32: =IF(D32="","",IF(OR(ISNUMBER(SEARCH("VISITA",D32)),ISNUMBER(SEARCH("RUTA",D32)),ISNUMBER(SEARCH("ARRIB",D32)),ISNUMBER(SEARCH("MATRIZ",D32)),ISNUMBER(SEARCH("PENDIENTE",D32))),"VISITA COORDINADA CON EL CLIENTE","N/A")) -> VISITA COORDINADA CON EL CLIENTE | G32: =IF(base!G32="","",base!G32) -> 001234 | H32: =IF(base!I32="","",base!I32) -> FLEX | I32: =IF(base!S32="","",base!S32) -> Prueba 30 | J32: =IF(base!T32="","",base!T32) -> Calle 123 Piso 2 | K32: =IF(base!U32="","",base!U32) | L32: =IF(base!Y32="","",base!Y32) | M32: =IF(base!AH32="","",base!AH32) | N32: =IF(base!AI32="","",base!AI32) -> 34.072273 | O32: =IF(base!BA32="","",base!BA32) -> 1875 | P32: =IF(base!BK32="","",base!BK32) -> 46303.806 | Q32: =IF(base!BS32="","",base!BS32)
A33: =IF(base!A33="","",base!A33) -> 6200031 | B33: =IF(base!BN33="","",base!BN33) -> 46303.625 | C33: =IF(base!C33="","",base!C33) -> ZETABURGOS SRL | D33: =IF(base!E33="","",base!E33) -> ENTREGADO | E33: =IF(base!BF33="","",base!BF33) | F33: =IF(D33="","",IF(OR(ISNUMBER(SEARCH("VISITA",D33)),ISNUMBER(SEARCH("RUTA",D33)),ISNUMBER(SEARCH("ARRIB",D33)),ISNUMBER(SEARCH("MATRIZ",D33)),ISNUMBER(SEARCH("PENDIENTE",D33))),"VISITA COORDINADA CON EL CLIENTE","N/A")) -> N/A | G33: ="#ABC" -> #ABC | H33: =IF(base!I33="","",base!I33) -> SAMEDAY | I33: =IF(base!S33="","",base!S33) -> Prueba 31 | J33: =IF(base!T33="","",base!T33) -> Calle 123 Piso 2 | K33: =IF(base!U33="","",base!U33) | L33: =IF(base!Y33="","",base!Y33) | M33: =IF(base!AH33="","",base!AH33) | N33: =IF(base!AI33="","",base!AI33) -> 34.072273 | O33: =IF(base!BA33="","",base!BA33) -> 1875 | P33: =IF(base!BK33="","",base!BK33) -> 46303.806 | Q33: =IF(base!BS33="","",base!BS33)
A34: =IF(base!A34="","",base!A34) -> 6200032 | B34: =IF(base!BN34="","",base!BN34) -> 46303.625 | C34: =IF(base!C34="","",base!C34) -> ZETABURGOS SRL | D34: =IF(base!E34="","",base!E34) -> REPROGRAMACIÓN | E34: =IF(base!BF34="","",base!BF34) | F34: =IF(D34="","",IF(OR(ISNUMBER(SEARCH("VISITA",D34)),ISNUMBER(SEARCH("RUTA",D34)),ISNUMBER(SEARCH("ARRIB",D34)),ISNUMBER(SEARCH("MATRIZ",D34)),ISNUMBER(SEARCH("PENDIENTE",D34))),"VISITA COORDINADA CON EL CLIENTE","N/A")) -> N/A | G34: =IF(base!G34="","",base!G34) -> 470123456 | H34: =IF(base!I34="","",base!I34) -> FLEX | I34: =IF(base!S34="","",base!S34) -> Prueba 32 | J34: =IF(base!T34="","",base!T34) -> Calle 123 Piso 2 | K34: =IF(base!U34="","",base!U34) | L34: =IF(base!Y34="","",base!Y34) | M34: =IF(base!AH34="","",base!AH34) | N34: =IF(base!AI34="","",base!AI34) -> 34.072273 | O34: =IF(base!BA34="","",base!BA34) -> 1875 | P34: =IF(base!BK34="","",base!BK34) -> 46303.806 | Q34: =IF(base!BS34="","",base!BS34)
A35: =IF(base!A35="","",base!A35) -> 6200033 | B35: =IF(base!BN35="","",base!BN35) -> 46303.625 | C35: =IF(base!C35="","",base!C35) -> ZETABURGOS SRL | D35: =IF(base!E35="","",base!E35) -> 1RVT - 1° VISITA | E35: =IF(base!BF35="","",base!BF35) | F35: =IF(D35="","",IF(OR(ISNUMBER(SEARCH("VISITA",D35)),ISNUMBER(SEARCH("RUTA",D35)),ISNUMBER(SEARCH("ARRIB",D35)),ISNUMBER(SEARCH("MATRIZ",D35)),ISNUMBER(SEARCH("PENDIENTE",D35))),"VISITA COORDINADA CON EL CLIENTE","N/A")) -> VISITA COORDINADA CON EL CLIENTE | G35: =IF(base!G35="","",base!G35) -> ABC001 | H35: =IF(base!I35="","",base!I35) -> SAMEDAY | I35: =IF(base!S35="","",base!S35) -> Prueba 33 | J35: =IF(base!T35="","",base!T35) -> Calle 123 Piso 2 | K35: =IF(base!U35="","",base!U35) | L35: =IF(base!Y35="","",base!Y35) | M35: =IF(base!AH35="","",base!AH35) | N35: =IF(base!AI35="","",base!AI35) -> 34.072273 | O35: =IF(base!BA35="","",base!BA35) -> 1875 | P35: =IF(base!BK35="","",base!BK35) -> 46303.806 | Q35: =IF(base!BS35="","",base!BS35)
A36: =IF(base!A36="","",base!A36) -> 6200034 | B36: =IF(base!BN36="","",base!BN36) -> 46303.625 | C36: =IF(base!C36="","",base!C36) -> ZETABURGOS SRL | D36: =IF(base!E36="","",base!E36) -> ENTREGADO | E36: =IF(base!BF36="","",base!BF36) | F36: =IF(D36="","",IF(OR(ISNUMBER(SEARCH("VISITA",D36)),ISNUMBER(SEARCH("RUTA",D36)),ISNUMBER(SEARCH("ARRIB",D36)),ISNUMBER(SEARCH("MATRIZ",D36)),ISNUMBER(SEARCH("PENDIENTE",D36))),"VISITA COORDINADA CON EL CLIENTE","N/A")) -> N/A | G36: =IF(base!G36="","",base!G36) -> 2000018857041302 | H36: =IF(base!I36="","",base!I36) -> FLEX | I36: =IF(base!S36="","",base!S36) -> Prueba 34 | J36: =IF(base!T36="","",base!T36) -> Calle 123 Piso 2 | K36: =IF(base!U36="","",base!U36) | L36: =IF(base!Y36="","",base!Y36) | M36: =IF(base!AH36="","",base!AH36) | N36: =IF(base!AI36="","",base!AI36) -> 34.072273 | O36: =IF(base!BA36="","",base!BA36) -> 1875 | P36: =IF(base!BK36="","",base!BK36) -> 46303.806 | Q36: =IF(base!BS36="","",base!BS36)
A37: =IF(base!A37="","",base!A37) -> 6200035 | B37: =IF(base!BN37="","",base!BN37) -> 46303.625 | C37: =IF(base!C37="","",base!C37) -> ZETABURGOS SRL | D37: =IF(base!E37="","",base!E37) -> REPROGRAMACIÓN | E37: =IF(base!BF37="","",base!BF37) | F37: =IF(D37="","",IF(OR(ISNUMBER(SEARCH("VISITA",D37)),ISNUMBER(SEARCH("RUTA",D37)),ISNUMBER(SEARCH("ARRIB",D37)),ISNUMBER(SEARCH("MATRIZ",D37)),ISNUMBER(SEARCH("PENDIENTE",D37))),"VISITA COORDINADA CON EL CLIENTE","N/A")) -> N/A | G37: =IF(base!G37="","",base!G37) -> 001234 | H37: =IF(base!I37="","",base!I37) -> FLEX | I37: =IF(base!S37="","",base!S37) -> Prueba 35 | J37: =IF(base!T37="","",base!T37) -> Calle 123 Piso 2 | K37: =IF(base!U37="","",base!U37) | L37: =IF(base!Y37="","",base!Y37) | M37: =IF(base!AH37="","",base!AH37) | N37: =IF(base!AI37="","",base!AI37) -> 34.072273 | O37: =IF(base!BA37="","",base!BA37) -> 1875 | P37: =IF(base!BK37="","",base!BK37) -> 46303.806 | Q37: =IF(base!BS37="","",base!BS37)
A38: =IF(base!A38="","",base!A38) -> 6200036 | B38: =IF(base!BN38="","",base!BN38) -> 46303.625 | C38: =IF(base!C38="","",base!C38) -> ZETABURGOS SRL | D38: =IF(base!E38="","",base!E38) -> 1RVT - 1° VISITA | E38: =IF(base!BF38="","",base!BF38) | F38: =IF(D38="","",IF(OR(ISNUMBER(SEARCH("VISITA",D38)),ISNUMBER(SEARCH("RUTA",D38)),ISNUMBER(SEARCH("ARRIB",D38)),ISNUMBER(SEARCH("MATRIZ",D38)),ISNUMBER(SEARCH("PENDIENTE",D38))),"VISITA COORDINADA CON EL CLIENTE","N/A")) -> VISITA COORDINADA CON EL CLIENTE | G38: ="#ABC" -> #ABC | H38: =IF(base!I38="","",base!I38) -> SAMEDAY | I38: =IF(base!S38="","",base!S38) -> Prueba 36 | J38: =IF(base!T38="","",base!T38) -> Calle 123 Piso 2 | K38: =IF(base!U38="","",base!U38) | L38: =IF(base!Y38="","",base!Y38) | M38: =IF(base!AH38="","",base!AH38) | N38: =IF(base!AI38="","",base!AI38) -> 34.072273 | O38: =IF(base!BA38="","",base!BA38) -> 1875 | P38: =IF(base!BK38="","",base!BK38) -> 46303.806 | Q38: =IF(base!BS38="","",base!BS38)
A39: =IF(base!A39="","",base!A39) -> 6200037 | B39: =IF(base!BN39="","",base!BN39) -> 46303.625 | C39: =IF(base!C39="","",base!C39) -> ZETABURGOS SRL | D39: =IF(base!E39="","",base!E39) -> ENTREGADO | E39: =IF(base!BF39="","",base!BF39) | F39: =IF(D39="","",IF(OR(ISNUMBER(SEARCH("VISITA",D39)),ISNUMBER(SEARCH("RUTA",D39)),ISNUMBER(SEARCH("ARRIB",D39)),ISNUMBER(SEARCH("MATRIZ",D39)),ISNUMBER(SEARCH("PENDIENTE",D39))),"VISITA COORDINADA CON EL CLIENTE","N/A")) -> N/A | G39: =IF(base!G39="","",base!G39) -> 470123456 | H39: =IF(base!I39="","",base!I39) -> FLEX | I39: =IF(base!S39="","",base!S39) -> Prueba 37 | J39: =IF(base!T39="","",base!T39) -> Calle 123 Piso 2 | K39: =IF(base!U39="","",base!U39) | L39: =IF(base!Y39="","",base!Y39) | M39: =IF(base!AH39="","",base!AH39) | N39: =IF(base!AI39="","",base!AI39) -> 34.072273 | O39: =IF(base!BA39="","",base!BA39) -> 1875 | P39: =IF(base!BK39="","",base!BK39) -> 46303.806 | Q39: =IF(base!BS39="","",base!BS39)
A40: =IF(base!A40="","",base!A40) -> 6200038 | B40: =IF(base!BN40="","",base!BN40) -> 46303.625 | C40: =IF(base!C40="","",base!C40) -> ZETABURGOS SRL | D40: =IF(base!E40="","",base!E40) -> REPROGRAMACIÓN | E40: =IF(base!BF40="","",base!BF40) | F40: =IF(D40="","",IF(OR(ISNUMBER(SEARCH("VISITA",D40)),ISNUMBER(SEARCH("RUTA",D40)),ISNUMBER(SEARCH("ARRIB",D40)),ISNUMBER(SEARCH("MATRIZ",D40)),ISNUMBER(SEARCH("PENDIENTE",D40))),"VISITA COORDINADA CON EL CLIENTE","N/A")) -> N/A | G40: =IF(base!G40="","",base!G40) -> ABC001 | H40: =IF(base!I40="","",base!I40) -> SAMEDAY | I40: =IF(base!S40="","",base!S40) -> Prueba 38 | J40: =IF(base!T40="","",base!T40) -> Calle 123 Piso 2 | K40: =IF(base!U40="","",base!U40) | L40: =IF(base!Y40="","",base!Y40) | M40: =IF(base!AH40="","",base!AH40) | N40: =IF(base!AI40="","",base!AI40) -> 34.072273 | O40: =IF(base!BA40="","",base!BA40) -> 1875 | P40: =IF(base!BK40="","",base!BK40) -> 46303.806 | Q40: =IF(base!BS40="","",base!BS40)
...

Sheet base
A1: Nro Guia | B1: Fecha | C1: Cliente | D1: Sucursal | E1: Estado | F1: Motivo | G1: Remito | H1: Guia Agente | I1: Servicio | J1: Tiempo | K1: Localidad Origen | L1: Localidad Destino | M1: Destino | N1: Peso | O1: Bultos | P1: Importe | Q1: Valor Declarado | R1: Empresa | S1: Destinatario | T1: Domicilio | U1: Localidad | V1: Provincia | W1: Email | X1: Horario | Y1: Distribuidor Recorrido | Z1: Distribuidor Origen | AA1: Distribuidor Destino | AB1: Fecha Planilla | AC1: Nro. Planilla | AD1: Fecha Rendicion | AE1: Nro. Rendicion | AF1: Fecha Pactada | AG1: Fecha Entrega | AH1: Recibio | AI1: Documento | AJ1: Lote | AK1: Contrareembolso | AL1: Other Info | AM1: Obs 1 | AN1: Obs 2 | AO1: Nro.Socio | AP1: Nro.Prestador | AQ1: Usuario | AR1: Peso Volumetrico | AS1: Volumen | AT1: Ceco | AU1: Importe Urgente | AV1: Kg Exceso | AW1: Importe Exceso | AX1: Sector | AY1: Trabajo | AZ1: Fecha Repactacion | BA1: CP | BB1: PLANILLA FACTURADO | BC1: CONSTANCIA RETIRO | BD1: SUCURSAL ORIGEN | BE1: SUCURSAL DESTINO | BF1: GRUPO | BG1: COM.OBS 3 | BH1: COM.OBS 4 | BI1: COM.OTHER INFO | BJ1: COM.CELULAR | BK1: FECHA ULTIMO ESTADO | BL1: Precinto | BM1: Codigo Sucursal | BN1: Fecha Ingreso a Planta | BO1: Datos Envios Obs | BP1: Pago En | BQ1: Codigo Sucursal Naranja Devolucion | BR1: Descripcion Sucursal Naranja Devolucion | BS1: Zona Destino | BT1: Sub Zona Destino | BU1: Nombre Fantasia | BV1: Nro.Liquidacion | BW1: Canal
A2: 6200000 | B2: 46303.806 | C2: ZETABURGOS SRL | E2: 1RVT - 1° VISITA | G2: 001234 | I2: FLEX | N2: 1.25 | S2: Prueba 0 | T2: Calle 123 Piso 2 | AI2: 34.072273 | BA2: 1875 | BJ2: 011123456 | BK2: 46303.806 | BN2: 46303.625
A3: 6200001 | B3: 46303.806 | C3: ZETABURGOS SRL | E3: ENTREGADO | G3: #ABC | I3: SAMEDAY | N3: 1.25 | S3: Prueba 1 | T3: Calle 123 Piso 2 | AI3: 34.072273 | BA3: 1875 | BJ3: 011123456 | BK3: 46303.806 | BN3: 46303.625
A4: 6200002 | B4: 46303.806 | C4: ZETABURGOS SRL | E4: REPROGRAMACIÓN | G4: 470123456 | I4: FLEX | N4: 1.25 | S4: Prueba 2 | T4: Calle 123 Piso 2 | AI4: 34.072273 | BA4: 1875 | BJ4: 011123456 | BK4: 46303.806 | BN4: 46303.625
A5: 6200003 | B5: 46303.806 | C5: ZETABURGOS SRL | E5: 1RVT - 1° VISITA | G5: ABC001 | I5: SAMEDAY | N5: 1.25 | S5: Prueba 3 | T5: Calle 123 Piso 2 | AI5: 34.072273 | BA5: 1875 | BJ5: 011123456 | BK5: 46303.806 | BN5: 46303.625
A6: 6200004 | B6: 46303.806 | C6: ZETABURGOS SRL | E6: ENTREGADO | G6: 2000018857041302 | I6: FLEX | N6: 1.25 | S6: Prueba 4 | T6: Calle 123 Piso 2 | AI6: 34.072273 | BA6: 1875 | BJ6: 011123456 | BK6: 46303.806 | BN6: 46303.625
A7: 6200005 | B7: 46303.806 | C7: ZETABURGOS SRL | E7: REPROGRAMACIÓN | G7: 001234 | I7: FLEX | N7: 1.25 | S7: Prueba 5 | T7: Calle 123 Piso 2 | AI7: 34.072273 | BA7: 1875 | BJ7: 011123456 | BK7: 46303.806 | BN7: 46303.625
A8: 6200006 | B8: 46303.806 | C8: ZETABURGOS SRL | E8: 1RVT - 1° VISITA | G8: #ABC | I8: SAMEDAY | N8: 1.25 | S8: Prueba 6 | T8: Calle 123 Piso 2 | AI8: 34.072273 | BA8: 1875 | BJ8: 011123456 | BK8: 46303.806 | BN8: 46303.625
A9: 6200007 | B9: 46303.806 | C9: ZETABURGOS SRL | E9: ENTREGADO | G9: 470123456 | I9: FLEX | N9: 1.25 | S9: Prueba 7 | T9: Calle 123 Piso 2 | AI9: 34.072273 | BA9: 1875 | BJ9: 011123456 | BK9: 46303.806 | BN9: 46303.625
A10: 6200008 | B10: 46303.806 | C10: ZETABURGOS SRL | E10: REPROGRAMACIÓN | G10: ABC001 | I10: SAMEDAY | N10: 1.25 | S10: Prueba 8 | T10: Calle 123 Piso 2 | AI10: 34.072273 | BA10: 1875 | BJ10: 011123456 | BK10: 46303.806 | BN10: 46303.625
A11: 6200009 | B11: 46303.806 | C11: ZETABURGOS SRL | E11: 1RVT - 1° VISITA | G11: 2000018857041302 | I11: FLEX | N11: 1.25 | S11: Prueba 9 | T11: Calle 123 Piso 2 | AI11: 34.072273 | BA11: 1875 | BJ11: 011123456 | BK11: 46303.806 | BN11: 46303.625
A12: 6200010 | B12: 46303.806 | C12: ZETABURGOS SRL | E12: ENTREGADO | G12: 001234 | I12: FLEX | N12: 1.25 | S12: Prueba 10 | T12: Calle 123 Piso 2 | AI12: 34.072273 | BA12: 1875 | BJ12: 011123456 | BK12: 46303.806 | BN12: 46303.625
A13: 6200011 | B13: 46303.806 | C13: ZETABURGOS SRL | E13: REPROGRAMACIÓN | G13: #ABC | I13: SAMEDAY | N13: 1.25 | S13: Prueba 11 | T13: Calle 123 Piso 2 | AI13: 34.072273 | BA13: 1875 | BJ13: 011123456 | BK13: 46303.806 | BN13: 46303.625
A14: 6200012 | B14: 46303.806 | C14: ZETABURGOS SRL | E14: 1RVT - 1° VISITA | G14: 470123456 | I14: FLEX | N14: 1.25 | S14: Prueba 12 | T14: Calle 123 Piso 2 | AI14: 34.072273 | BA14: 1875 | BJ14: 011123456 | BK14: 46303.806 | BN14: 46303.625
A15: 6200013 | B15: 46303.806 | C15: ZETABURGOS SRL | E15: ENTREGADO | G15: ABC001 | I15: SAMEDAY | N15: 1.25 | S15: Prueba 13 | T15: Calle 123 Piso 2 | AI15: 34.072273 | BA15: 1875 | BJ15: 011123456 | BK15: 46303.806 | BN15: 46303.625
A16: 6200014 | B16: 46303.806 | C16: ZETABURGOS SRL | E16: REPROGRAMACIÓN | G16: 2000018857041302 | I16: FLEX | N16: 1.25 | S16: Prueba 14 | T16: Calle 123 Piso 2 | AI16: 34.072273 | BA16: 1875 | BJ16: 011123456 | BK16: 46303.806 | BN16: 46303.625
A17: 6200015 | B17: 46303.806 | C17: ZETABURGOS SRL | E17: 1RVT - 1° VISITA | G17: 001234 | I17: FLEX | N17: 1.25 | S17: Prueba 15 | T17: Calle 123 Piso 2 | AI17: 34.072273 | BA17: 1875 | BJ17: 011123456 | BK17: 46303.806 | BN17: 46303.625
A18: 6200016 | B18: 46303.806 | C18: ZETABURGOS SRL | E18: ENTREGADO | G18: #ABC | I18: SAMEDAY | N18: 1.25 | S18: Prueba 16 | T18: Calle 123 Piso 2 | AI18: 34.072273 | BA18: 1875 | BJ18: 011123456 | BK18: 46303.806 | BN18: 46303.625
A19: 6200017 | B19: 46303.806 | C19: ZETABURGOS SRL | E19: REPROGRAMACIÓN | G19: 470123456 | I19: FLEX | N19: 1.25 | S19: Prueba 17 | T19: Calle 123 Piso 2 | AI19: 34.072273 | BA19: 1875 | BJ19: 011123456 | BK19: 46303.806 | BN19: 46303.625
A20: 6200018 | B20: 46303.806 | C20: ZETABURGOS SRL | E20: 1RVT - 1° VISITA | G20: ABC001 | I20: SAMEDAY | N20: 1.25 | S20: Prueba 18 | T20: Calle 123 Piso 2 | AI20: 34.072273 | BA20: 1875 | BJ20: 011123456 | BK20: 46303.806 | BN20: 46303.625
A21: 6200019 | B21: 46303.806 | C21: ZETABURGOS SRL | E21: ENTREGADO | G21: 2000018857041302 | I21: FLEX | N21: 1.25 | S21: Prueba 19 | T21: Calle 123 Piso 2 | AI21: 34.072273 | BA21: 1875 | BJ21: 011123456 | BK21: 46303.806 | BN21: 46303.625
A22: 6200020 | B22: 46303.806 | C22: ZETABURGOS SRL | E22: REPROGRAMACIÓN | G22: 001234 | I22: FLEX | N22: 1.25 | S22: Prueba 20 | T22: Calle 123 Piso 2 | AI22: 34.072273 | BA22: 1875 | BJ22: 011123456 | BK22: 46303.806 | BN22: 46303.625
A23: 6200021 | B23: 46303.806 | C23: ZETABURGOS SRL | E23: 1RVT - 1° VISITA | G23: #ABC | I23: SAMEDAY | N23: 1.25 | S23: Prueba 21 | T23: Calle 123 Piso 2 | AI23: 34.072273 | BA23: 1875 | BJ23: 011123456 | BK23: 46303.806 | BN23: 46303.625
A24: 6200022 | B24: 46303.806 | C24: ZETABURGOS SRL | E24: ENTREGADO | G24: 470123456 | I24: FLEX | N24: 1.25 | S24: Prueba 22 | T24: Calle 123 Piso 2 | AI24: 34.072273 | BA24: 1875 | BJ24: 011123456 | BK24: 46303.806 | BN24: 46303.625
A25: 6200023 | B25: 46303.806 | C25: ZETABURGOS SRL | E25: REPROGRAMACIÓN | G25: ABC001 | I25: SAMEDAY | N25: 1.25 | S25: Prueba 23 | T25: Calle 123 Piso 2 | AI25: 34.072273 | BA25: 1875 | BJ25: 011123456 | BK25: 46303.806 | BN25: 46303.625
A26: 6200024 | B26: 46303.806 | C26: ZETABURGOS SRL | E26: 1RVT - 1° VISITA | G26: 2000018857041302 | I26: FLEX | N26: 1.25 | S26: Prueba 24 | T26: Calle 123 Piso 2 | AI26: 34.072273 | BA26: 1875 | BJ26: 011123456 | BK26: 46303.806 | BN26: 46303.625
A27: 6200025 | B27: 46303.806 | C27: ZETABURGOS SRL | E27: ENTREGADO | G27: 001234 | I27: FLEX | N27: 1.25 | S27: Prueba 25 | T27: Calle 123 Piso 2 | AI27: 34.072273 | BA27: 1875 | BJ27: 011123456 | BK27: 46303.806 | BN27: 46303.625
A28: 6200026 | B28: 46303.806 | C28: ZETABURGOS SRL | E28: REPROGRAMACIÓN | G28: #ABC | I28: SAMEDAY | N28: 1.25 | S28: Prueba 26 | T28: Calle 123 Piso 2 | AI28: 34.072273 | BA28: 1875 | BJ28: 011123456 | BK28: 46303.806 | BN28: 46303.625
A29: 6200027 | B29: 46303.806 | C29: ZETABURGOS SRL | E29: 1RVT - 1° VISITA | G29: 470123456 | I29: FLEX | N29: 1.25 | S29: Prueba 27 | T29: Calle 123 Piso 2 | AI29: 34.072273 | BA29: 1875 | BJ29: 011123456 | BK29: 46303.806 | BN29: 46303.625
A30: 6200028 | B30: 46303.806 | C30: ZETABURGOS SRL | E30: ENTREGADO | G30: ABC001 | I30: SAMEDAY | N30: 1.25 | S30: Prueba 28 | T30: Calle 123 Piso 2 | AI30: 34.072273 | BA30: 1875 | BJ30: 011123456 | BK30: 46303.806 | BN30: 46303.625
A31: 6200029 | B31: 46303.806 | C31: ZETABURGOS SRL | E31: REPROGRAMACIÓN | G31: 2000018857041302 | I31: FLEX | N31: 1.25 | S31: Prueba 29 | T31: Calle 123 Piso 2 | AI31: 34.072273 | BA31: 1875 | BJ31: 011123456 | BK31: 46303.806 | BN31: 46303.625
A32: 6200030 | B32: 46303.806 | C32: ZETABURGOS SRL | E32: 1RVT - 1° VISITA | G32: 001234 | I32: FLEX | N32: 1.25 | S32: Prueba 30 | T32: Calle 123 Piso 2 | AI32: 34.072273 | BA32: 1875 | BJ32: 011123456 | BK32: 46303.806 | BN32: 46303.625
A33: 6200031 | B33: 46303.806 | C33: ZETABURGOS SRL | E33: ENTREGADO | G33: #ABC | I33: SAMEDAY | N33: 1.25 | S33: Prueba 31 | T33: Calle 123 Piso 2 | AI33: 34.072273 | BA33: 1875 | BJ33: 011123456 | BK33: 46303.806 | BN33: 46303.625
A34: 6200032 | B34: 46303.806 | C34: ZETABURGOS SRL | E34: REPROGRAMACIÓN | G34: 470123456 | I34: FLEX | N34: 1.25 | S34: Prueba 32 | T34: Calle 123 Piso 2 | AI34: 34.072273 | BA34: 1875 | BJ34: 011123456 | BK34: 46303.806 | BN34: 46303.625
A35: 6200033 | B35: 46303.806 | C35: ZETABURGOS SRL | E35: 1RVT - 1° VISITA | G35: ABC001 | I35: SAMEDAY | N35: 1.25 | S35: Prueba 33 | T35: Calle 123 Piso 2 | AI35: 34.072273 | BA35: 1875 | BJ35: 011123456 | BK35: 46303.806 | BN35: 46303.625
A36: 6200034 | B36: 46303.806 | C36: ZETABURGOS SRL | E36: ENTREGADO | G36: 2000018857041302 | I36: FLEX | N36: 1.25 | S36: Prueba 34 | T36: Calle 123 Piso 2 | AI36: 34.072273 | BA36: 1875 | BJ36: 011123456 | BK36: 46303.806 | BN36: 46303.625
A37: 6200035 | B37: 46303.806 | C37: ZETABURGOS SRL | E37: REPROGRAMACIÓN | G37: 001234 | I37: FLEX | N37: 1.25 | S37: Prueba 35 | T37: Calle 123 Piso 2 | AI37: 34.072273 | BA37: 1875 | BJ37: 011123456 | BK37: 46303.806 | BN37: 46303.625
A38: 6200036 | B38: 46303.806 | C38: ZETABURGOS SRL | E38: 1RVT - 1° VISITA | G38: #ABC | I38: SAMEDAY | N38: 1.25 | S38: Prueba 36 | T38: Calle 123 Piso 2 | AI38: 34.072273 | BA38: 1875 | BJ38: 011123456 | BK38: 46303.806 | BN38: 46303.625
A39: 6200037 | B39: 46303.806 | C39: ZETABURGOS SRL | E39: ENTREGADO | G39: 470123456 | I39: FLEX | N39: 1.25 | S39: Prueba 37 | T39: Calle 123 Piso 2 | AI39: 34.072273 | BA39: 1875 | BJ39: 011123456 | BK39: 46303.806 | BN39: 46303.625
A40: 6200038 | B40: 46303.806 | C40: ZETABURGOS SRL | E40: REPROGRAMACIÓN | G40: ABC001 | I40: SAMEDAY | N40: 1.25 | S40: Prueba 38 | T40: Calle 123 Piso 2 | AI40: 34.072273 | BA40: 1875 | BJ40: 011123456 | BK40: 46303.806 | BN40: 46303.625
...

Sheet aux
A1: VISITA COORDINADA CON EL CLIENTE
A2: N/A
A3: CERRADO EN APP FLEX
